[2021-07-23 16:55:43,846] {taskinstance.py:896} INFO - Dependencies all met for <TaskInstance: hello_world.load_to_db 2021-07-23T13:55:38.704560+00:00 [queued]>
[2021-07-23 16:55:43,858] {taskinstance.py:896} INFO - Dependencies all met for <TaskInstance: hello_world.load_to_db 2021-07-23T13:55:38.704560+00:00 [queued]>
[2021-07-23 16:55:43,858] {taskinstance.py:1087} INFO - 
--------------------------------------------------------------------------------
[2021-07-23 16:55:43,859] {taskinstance.py:1088} INFO - Starting attempt 1 of 2
[2021-07-23 16:55:43,859] {taskinstance.py:1089} INFO - 
--------------------------------------------------------------------------------
[2021-07-23 16:55:43,882] {taskinstance.py:1107} INFO - Executing <Task(BashOperator): load_to_db> on 2021-07-23T13:55:38.704560+00:00
[2021-07-23 16:55:43,885] {standard_task_runner.py:52} INFO - Started process 6875 to run task
[2021-07-23 16:55:43,890] {standard_task_runner.py:76} INFO - Running: ['airflow', 'tasks', 'run', 'hello_world', 'load_to_db', '2021-07-23T13:55:38.704560+00:00', '--job-id', '49', '--pool', 'default_pool', '--raw', '--subdir', 'DAGS_FOLDER/simple_dag.py', '--cfg-path', '/tmp/tmpvi5aey33', '--error-file', '/tmp/tmp3qn4uyqp']
[2021-07-23 16:55:43,892] {standard_task_runner.py:77} INFO - Job 49: Subtask load_to_db
[2021-07-23 16:55:43,950] {logging_mixin.py:104} INFO - Running <TaskInstance: hello_world.load_to_db 2021-07-23T13:55:38.704560+00:00 [running]> on host DESKTOP-JHC8U0L.localdomain
[2021-07-23 16:55:44,024] {taskinstance.py:1300} INFO - Exporting the following env vars:
AIRFLOW_CTX_DAG_EMAIL=airflow@example.com
AIRFLOW_CTX_DAG_OWNER=airflow
AIRFLOW_CTX_DAG_ID=hello_world
AIRFLOW_CTX_TASK_ID=load_to_db
AIRFLOW_CTX_EXECUTION_DATE=2021-07-23T13:55:38.704560+00:00
AIRFLOW_CTX_DAG_RUN_ID=manual__2021-07-23T13:55:38.704560+00:00
[2021-07-23 16:55:44,025] {subprocess.py:52} INFO - Tmp dir root location: 
 /tmp
[2021-07-23 16:55:44,025] {subprocess.py:63} INFO - Running command: ['bash', '-c', 'python3 /load_to_db.py']
[2021-07-23 16:55:44,032] {subprocess.py:74} INFO - Output:
[2021-07-23 16:55:44,077] {subprocess.py:78} INFO - python3: can't open file '/load_to_db.py': [Errno 2] No such file or directory
[2021-07-23 16:55:44,080] {subprocess.py:82} INFO - Command exited with return code 2
[2021-07-23 16:55:44,100] {taskinstance.py:1501} ERROR - Task failed with exception
Traceback (most recent call last):
  File "/home/dennismutia/.virtualenvs/wefarm/lib/python3.8/site-packages/airflow/models/taskinstance.py", line 1157, in _run_raw_task
    self._prepare_and_execute_task_with_callbacks(context, task)
  File "/home/dennismutia/.virtualenvs/wefarm/lib/python3.8/site-packages/airflow/models/taskinstance.py", line 1331, in _prepare_and_execute_task_with_callbacks
    result = self._execute_task(context, task_copy)
  File "/home/dennismutia/.virtualenvs/wefarm/lib/python3.8/site-packages/airflow/models/taskinstance.py", line 1361, in _execute_task
    result = task_copy.execute(context=context)
  File "/home/dennismutia/.virtualenvs/wefarm/lib/python3.8/site-packages/airflow/operators/bash.py", line 176, in execute
    raise AirflowException('Bash command failed. The command returned a non-zero exit code.')
airflow.exceptions.AirflowException: Bash command failed. The command returned a non-zero exit code.
[2021-07-23 16:55:44,102] {taskinstance.py:1544} INFO - Marking task as UP_FOR_RETRY. dag_id=hello_world, task_id=load_to_db, execution_date=20210723T135538, start_date=20210723T135543, end_date=20210723T135544
[2021-07-23 16:55:44,144] {local_task_job.py:149} INFO - Task exited with return code 1
